2020-05-03 23:20:08,645 DEBUG    root            Loaded Command Group: ['gcloud', 'projects']
2020-05-03 23:20:08,646 DEBUG    root            Loaded Command Group: ['gcloud', 'projects', 'describe']
2020-05-03 23:20:08,647 DEBUG    root            Running [gcloud.projects.describe] with arguments: [--account: "bram.musuko@gmail.com", --configuration: "default", --format: "value(name)", PROJECT_ID: "celtic-vent-271705"]
2020-05-03 23:20:08,667 DEBUG    root            Caught server not found error, retrying: Unable to find the server at cloudresourcemanager.googleapis.com
2020-05-03 23:20:08,667 DEBUG    root            Retrying request to url https://cloudresourcemanager.googleapis.com/v1/projects/celtic-vent-271705?alt=json after exception Unable to find the server at cloudresourcemanager.googleapis.com
2020-05-03 23:20:10,788 DEBUG    root            Caught server not found error, retrying: Unable to find the server at cloudresourcemanager.googleapis.com
2020-05-03 23:20:10,788 DEBUG    root            Retrying request to url https://cloudresourcemanager.googleapis.com/v1/projects/celtic-vent-271705?alt=json after exception Unable to find the server at cloudresourcemanager.googleapis.com
2020-05-03 23:20:14,862 DEBUG    root            Caught server not found error, retrying: Unable to find the server at cloudresourcemanager.googleapis.com
2020-05-03 23:20:14,862 DEBUG    root            Retrying request to url https://cloudresourcemanager.googleapis.com/v1/projects/celtic-vent-271705?alt=json after exception Unable to find the server at cloudresourcemanager.googleapis.com
2020-05-03 23:20:23,197 DEBUG    root            Caught server not found error, retrying: Unable to find the server at cloudresourcemanager.googleapis.com
2020-05-03 23:20:23,197 DEBUG    root            Retrying request to url https://cloudresourcemanager.googleapis.com/v1/projects/celtic-vent-271705?alt=json after exception Unable to find the server at cloudresourcemanager.googleapis.com
2020-05-03 23:20:36,615 DEBUG    root            Unable to find the server at cloudresourcemanager.googleapis.com
Traceback (most recent call last):
  File "/opt/google-cloud-sdk/lib/third_party/httplib2/python3/httplib2/__init__.py", line 1532, in _conn_request
    conn.connect()
  File "/opt/google-cloud-sdk/lib/third_party/httplib2/python3/httplib2/__init__.py", line 1284, in connect
    address_info = socket.getaddrinfo(host, port, 0, socket.SOCK_STREAM)
  File "/usr/lib/python3.8/socket.py", line 918, in getaddrinfo
    for res in _socket.getaddrinfo(host, port, family, type, proto, flags):
socket.gaierror: [Errno -3] Temporary failure in name resolution

During handling of the above exception, another exception occurred:

Traceback (most recent call last):
  File "/opt/google-cloud-sdk/lib/googlecloudsdk/calliope/cli.py", line 983, in Execute
    resources = calliope_command.Run(cli=self, args=args)
  File "/opt/google-cloud-sdk/lib/googlecloudsdk/calliope/backend.py", line 807, in Run
    resources = command_instance.Run(args)
  File "/opt/google-cloud-sdk/lib/surface/projects/describe.py", line 51, in Run
    return projects_api.Get(project_ref)
  File "/opt/google-cloud-sdk/lib/googlecloudsdk/api_lib/cloudresourcemanager/projects_api.py", line 74, in Get
    return client.projects.Get(
  File "/opt/google-cloud-sdk/lib/googlecloudsdk/third_party/apis/cloudresourcemanager/v1/cloudresourcemanager_v1_client.py", line 859, in Get
    return self._RunMethod(
  File "/opt/google-cloud-sdk/lib/third_party/apitools/base/py/base_api.py", line 728, in _RunMethod
    http_response = http_wrapper.MakeRequest(
  File "/opt/google-cloud-sdk/lib/third_party/apitools/base/py/http_wrapper.py", line 344, in MakeRequest
    return _MakeRequestNoRetry(
  File "/opt/google-cloud-sdk/lib/third_party/apitools/base/py/http_wrapper.py", line 393, in _MakeRequestNoRetry
    info, content = http.request(
  File "/opt/google-cloud-sdk/lib/googlecloudsdk/core/http.py", line 351, in WrappedRequest
    response = orig_request(*modified_args, **kwargs)
  File "/opt/google-cloud-sdk/lib/third_party/oauth2client/transport.py", line 167, in new_request
    resp, content = orig_request_method(uri, method, body,
  File "/opt/google-cloud-sdk/lib/googlecloudsdk/core/http.py", line 351, in WrappedRequest
    response = orig_request(*modified_args, **kwargs)
  File "/opt/google-cloud-sdk/lib/third_party/httplib2/python3/httplib2/__init__.py", line 1953, in request
    (response, content) = self._request(
  File "/opt/google-cloud-sdk/lib/third_party/httplib2/python3/httplib2/__init__.py", line 1625, in _request
    (response, content) = self._conn_request(
  File "/opt/google-cloud-sdk/lib/third_party/httplib2/python3/httplib2/__init__.py", line 1539, in _conn_request
    raise ServerNotFoundError("Unable to find the server at %s" % conn.host)
httplib2.python3.httplib2.ServerNotFoundError: Unable to find the server at cloudresourcemanager.googleapis.com
2020-05-03 23:20:36,617 ERROR    ___FILE_ONLY___ BEGIN CRASH STACKTRACE
Traceback (most recent call last):
  File "/opt/google-cloud-sdk/lib/third_party/httplib2/python3/httplib2/__init__.py", line 1532, in _conn_request
    conn.connect()
  File "/opt/google-cloud-sdk/lib/third_party/httplib2/python3/httplib2/__init__.py", line 1284, in connect
    address_info = socket.getaddrinfo(host, port, 0, socket.SOCK_STREAM)
  File "/usr/lib/python3.8/socket.py", line 918, in getaddrinfo
    for res in _socket.getaddrinfo(host, port, family, type, proto, flags):
socket.gaierror: [Errno -3] Temporary failure in name resolution

During handling of the above exception, another exception occurred:

Traceback (most recent call last):
  File "/opt/google-cloud-sdk/lib/googlecloudsdk/gcloud_main.py", line 186, in main
    gcloud_cli.Execute()
  File "/opt/google-cloud-sdk/lib/googlecloudsdk/calliope/cli.py", line 1009, in Execute
    self._HandleAllErrors(exc, command_path_string, specified_arg_names)
  File "/opt/google-cloud-sdk/lib/googlecloudsdk/calliope/cli.py", line 1042, in _HandleAllErrors
    exceptions.HandleError(exc, command_path_string, self.__known_error_handler)
  File "/opt/google-cloud-sdk/lib/googlecloudsdk/calliope/exceptions.py", line 527, in HandleError
    core_exceptions.reraise(exc)
  File "/opt/google-cloud-sdk/lib/googlecloudsdk/core/exceptions.py", line 146, in reraise
    six.reraise(type(exc_value), exc_value, tb)
  File "/opt/google-cloud-sdk/lib/third_party/six/__init__.py", line 693, in reraise
    raise value
  File "/opt/google-cloud-sdk/lib/googlecloudsdk/calliope/cli.py", line 983, in Execute
    resources = calliope_command.Run(cli=self, args=args)
  File "/opt/google-cloud-sdk/lib/googlecloudsdk/calliope/backend.py", line 807, in Run
    resources = command_instance.Run(args)
  File "/opt/google-cloud-sdk/lib/surface/projects/describe.py", line 51, in Run
    return projects_api.Get(project_ref)
  File "/opt/google-cloud-sdk/lib/googlecloudsdk/api_lib/cloudresourcemanager/projects_api.py", line 74, in Get
    return client.projects.Get(
  File "/opt/google-cloud-sdk/lib/googlecloudsdk/third_party/apis/cloudresourcemanager/v1/cloudresourcemanager_v1_client.py", line 859, in Get
    return self._RunMethod(
  File "/opt/google-cloud-sdk/lib/third_party/apitools/base/py/base_api.py", line 728, in _RunMethod
    http_response = http_wrapper.MakeRequest(
  File "/opt/google-cloud-sdk/lib/third_party/apitools/base/py/http_wrapper.py", line 344, in MakeRequest
    return _MakeRequestNoRetry(
  File "/opt/google-cloud-sdk/lib/third_party/apitools/base/py/http_wrapper.py", line 393, in _MakeRequestNoRetry
    info, content = http.request(
  File "/opt/google-cloud-sdk/lib/googlecloudsdk/core/http.py", line 351, in WrappedRequest
    response = orig_request(*modified_args, **kwargs)
  File "/opt/google-cloud-sdk/lib/third_party/oauth2client/transport.py", line 167, in new_request
    resp, content = orig_request_method(uri, method, body,
  File "/opt/google-cloud-sdk/lib/googlecloudsdk/core/http.py", line 351, in WrappedRequest
    response = orig_request(*modified_args, **kwargs)
  File "/opt/google-cloud-sdk/lib/third_party/httplib2/python3/httplib2/__init__.py", line 1953, in request
    (response, content) = self._request(
  File "/opt/google-cloud-sdk/lib/third_party/httplib2/python3/httplib2/__init__.py", line 1625, in _request
    (response, content) = self._conn_request(
  File "/opt/google-cloud-sdk/lib/third_party/httplib2/python3/httplib2/__init__.py", line 1539, in _conn_request
    raise ServerNotFoundError("Unable to find the server at %s" % conn.host)
httplib2.python3.httplib2.ServerNotFoundError: Unable to find the server at cloudresourcemanager.googleapis.com
2020-05-03 23:20:36,618 ERROR    root            gcloud crashed (ServerNotFoundError): Unable to find the server at cloudresourcemanager.googleapis.com
2020-05-03 23:20:36,618 INFO     ___FILE_ONLY___ 
If you would like to report this issue, please run the following command:

2020-05-03 23:20:36,618 INFO     ___FILE_ONLY___   gcloud feedback

2020-05-03 23:20:36,618 INFO     ___FILE_ONLY___ 
To check gcloud for common problems, please run the following command:

2020-05-03 23:20:36,619 INFO     ___FILE_ONLY___   gcloud info --run-diagnostics

